<?xml version="1.0"?>
<robot xmlns:xacro="http://www.ros.org/wiki/xacro">

    <!-- Steering joints -->
    <joint name="front_left_wheel_steering_joint" type="revolute">
        <child link="front_left_wheel_steering_link" />
        <parent link="base_link" />

        <axis xyz="0 0 1" />
        <limit lower="-0.6" upper="+0.6"
               velocity="1.0" effort="25" />
    </joint>

    <joint name="front_right_wheel_steering_joint" type="revolute">
        <child link="front_right_wheel_steering_link" />
        <parent link="base_link" />

        <axis xyz="0 0 1" />
        <limit lower="-0.6" upper="+0.6"
               velocity="1.0" effort="25" />
    </joint>

    <!-- Drive joints -->
    <joint name="front_left_wheel_joint" type="continuous">
        <child link="front_left_wheel" />
        <parent link="front_left_wheel_steering_link" />

        <axis xyz="0 0 1" />
    </joint>

    <joint name="front_right_wheel_joint" type="continuous">
        <child link="front_right_wheel" />
        <parent link="front_right_wheel_steering_link" />

        <axis xyz="0 0 1" />
    </joint>


    <joint name="rear_left_wheel_joint" type="continuous">
        <child link="rear_left_wheel" />
        <parent link="base_link" />

        <axis xyz="0 0 1" />
    </joint>

    <joint name="rear_right_wheel_joint" type="continuous">
        <child link="rear_right_wheel" />
        <parent link="base_link" />

        <axis xyz="0 0 1" />
    </joint>


</robot>