<?xml version="1.0" ?>
<!-- =================================================================================== -->
<!-- |    This document was autogenerated by xacro from urdf/robot.urdf.xacro          | -->
<!-- |    EDITING THIS FILE BY HAND IS NOT RECOMMENDED                                 | -->
<!-- =================================================================================== -->
<robot name="robot">
  <!-- link to full docs: https://github.com/UOA-FSAE/f1tenth/wiki/Description -->
  <!--
    https://github.com/UOA-FSAE/f1tenth/wiki/Description#cylinder_link

    This macro creates a cylinder link
    params:
    > name: name of link
    > mesh_file: link to stl or dae, example `package://f1tenth_description/meshes/chassis_base.stl`
    > radius: radius of wheel (m)
    > width: width of wheel (m)
    > mass: mass of wheel (kg)
    > *origin: need to include origin tag `<origin xyz="0 0 0" rpy="0 0 0"/>`

    example: Create a front left wheel with the name of the link being front_left_wheel, mesh located at the
    f1tenth_description package in the meshes folder called wheel.stl, radius of 0.055m, width of 0.0445m,
    and mass of 0.09kg with a default origin.

    ``` XACRO / XML
    <xacro:cylinder_link name="front_left_wheel" mesh_file="package://f1tenth_description/meshes/wheel.stl"
                 radius="0.055" width="0.0445" mass="0.09">
        <origin xyz="0 0 0" rpy="0 0 0"/>
    <xacro:wheel />
    ```

    There is a no mesh option it's called cylinder_link_nomesh that has the same params just with no mesh.
    -->
  <!--
    https://github.com/UOA-FSAE/f1tenth/wiki/Description#box_link

    This macro creates a box link
    params:
    > name: name of link
    > mesh_file: link to stl or dae, example `package://f1tenth_description/meshes/chassis_base.stl`
    > mass: mass of part (kg)
    > x: length of part (m)
    > y: height of part (m)
    > z: width of part (m)
    > *origin: need to include origin tag `<origin xyz="0 0 0" rpy="0 0 0"/>`

    example: Create a lower chassis part with the name of the link being lower_chassis, mesh located at the
    f1tenth_description package in the meshes folder called lower_chassis.stl with a mass of 0.08kg,
    length of 0.31m, width of 0.183m, and a height of 0.03m with its origin being set to 0 0 0.

    ``` XACRO / XML
    <xacro:box_link name="lower_chassis" mesh_file="package://f1tenth_description/meshes/lower_chassis.stl"
                    x="0.31" y="0.183" z="0.03" mass="0.08">
        <origin xyz="0 0 0" rpy="0 0 0"/>
    <xacro:box_link />
    ```
    -->
  <link name="base_link"/>
  <link name="front_left_wheel">
    <visual>
      <geometry>
        <mesh filename="package://f1tenth_description/meshes/wheel.stl" scale="0.001 0.001 0.001"/>
      </geometry>
      <origin rpy="-1.5707963267948966 0 0" xyz="0 0 0"/>
    </visual>
    <collision>
      <geometry>
        <mesh filename="package://f1tenth_description/meshes/wheel.stl" scale="0.001 0.001 0.001"/>
      </geometry>
      <origin rpy="-1.5707963267948966 0 0" xyz="0 0 0"/>
    </collision>
    <inertial>
      <origin rpy="-1.5707963267948966 0 0" xyz="0 0 0"/>
      <mass value="0.09"/>
      <inertia ixx="8.291437499999999e-05" ixy="0.0" ixz="0.0" iyy="8.291437499999999e-05" iyz="0.0" izz="0.000136125"/>
    </inertial>
  </link>
  <link name="front_right_wheel">
    <visual>
      <geometry>
        <mesh filename="package://f1tenth_description/meshes/wheel.stl" scale="0.001 0.001 0.001"/>
      </geometry>
      <origin rpy="1.5707963267948966 0 0" xyz="0 0 0"/>
    </visual>
    <collision>
      <geometry>
        <mesh filename="package://f1tenth_description/meshes/wheel.stl" scale="0.001 0.001 0.001"/>
      </geometry>
      <origin rpy="1.5707963267948966 0 0" xyz="0 0 0"/>
    </collision>
    <inertial>
      <origin rpy="1.5707963267948966 0 0" xyz="0 0 0"/>
      <mass value="0.09"/>
      <inertia ixx="8.291437499999999e-05" ixy="0.0" ixz="0.0" iyy="8.291437499999999e-05" iyz="0.0" izz="0.000136125"/>
    </inertial>
  </link>
  <link name="rear_left_wheel">
    <visual>
      <geometry>
        <mesh filename="package://f1tenth_description/meshes/wheel.stl" scale="0.001 0.001 0.001"/>
      </geometry>
      <origin rpy="-1.5707963267948966 0 0" xyz="0 0 0"/>
    </visual>
    <collision>
      <geometry>
        <mesh filename="package://f1tenth_description/meshes/wheel.stl" scale="0.001 0.001 0.001"/>
      </geometry>
      <origin rpy="-1.5707963267948966 0 0" xyz="0 0 0"/>
    </collision>
    <inertial>
      <origin rpy="-1.5707963267948966 0 0" xyz="0 0 0"/>
      <mass value="0.09"/>
      <inertia ixx="8.291437499999999e-05" ixy="0.0" ixz="0.0" iyy="8.291437499999999e-05" iyz="0.0" izz="0.000136125"/>
    </inertial>
  </link>
  <link name="rear_right_wheel">
    <visual>
      <geometry>
        <mesh filename="package://f1tenth_description/meshes/wheel.stl" scale="0.001 0.001 0.001"/>
      </geometry>
      <origin rpy="1.5707963267948966 0 0" xyz="0 0 0"/>
    </visual>
    <collision>
      <geometry>
        <mesh filename="package://f1tenth_description/meshes/wheel.stl" scale="0.001 0.001 0.001"/>
      </geometry>
      <origin rpy="1.5707963267948966 0 0" xyz="0 0 0"/>
    </collision>
    <inertial>
      <origin rpy="1.5707963267948966 0 0" xyz="0 0 0"/>
      <mass value="0.09"/>
      <inertia ixx="8.291437499999999e-05" ixy="0.0" ixz="0.0" iyy="8.291437499999999e-05" iyz="0.0" izz="0.000136125"/>
    </inertial>
  </link>
  <link name="front_left_wheel_steering_link">
    <visual>
      <geometry>
        <cylinder length="0.01" radius="0.003"/>
      </geometry>
      <origin rpy="0 0 0" xyz="0 0 0"/>
    </visual>
    <collision>
      <geometry>
        <cylinder length="0.01" radius="0.003"/>
      </geometry>
      <origin rpy="0 0 0" xyz="0 0 0"/>
    </collision>
    <inertial>
      <origin rpy="0 0 0" xyz="0 0 0"/>
      <mass value="0.05"/>
      <inertia ixx="5.291666666666666e-07" ixy="0.0" ixz="0.0" iyy="5.291666666666666e-07" iyz="0.0" izz="2.2500000000000002e-07"/>
    </inertial>
  </link>
  <link name="front_right_wheel_steering_link">
    <visual>
      <geometry>
        <cylinder length="0.01" radius="0.003"/>
      </geometry>
      <origin rpy="0 0 0" xyz="0 0 0"/>
    </visual>
    <collision>
      <geometry>
        <cylinder length="0.01" radius="0.003"/>
      </geometry>
      <origin rpy="0 0 0" xyz="0 0 0"/>
    </collision>
    <inertial>
      <origin rpy="0 0 0" xyz="0 0 0"/>
      <mass value="0.05"/>
      <inertia ixx="5.291666666666666e-07" ixy="0.0" ixz="0.0" iyy="5.291666666666666e-07" iyz="0.0" izz="2.2500000000000002e-07"/>
    </inertial>
  </link>
  <link name="lower_chassis">
    <visual>
      <geometry>
        <mesh filename="package://f1tenth_description/meshes/chassis_base.stl" scale="0.001 0.001 0.001"/>
      </geometry>
      <origin rpy="0 0 -1.5707963267948966" xyz="0 0 0"/>
    </visual>
    <collision>
      <geometry>
        <mesh filename="package://f1tenth_description/meshes/chassis_base.stl" scale="0.001 0.001 0.001"/>
      </geometry>
      <origin rpy="0 0 -1.5707963267948966" xyz="0 0 0"/>
    </collision>
    <inertial>
      <origin rpy="0 0 -1.5707963267948966" xyz="0 0 0"/>
      <mass value="0.08"/>
      <inertia ixx="0.00022925999999999996" ixy="0.0" ixz="0.0" iyy="0.0006466666666666666" iyz="0.0" izz="0.0008639266666666666"/>
    </inertial>
  </link>
  <!-- Steering joints -->
  <joint name="front_left_wheel_steering_joint" type="revolute">
    <child link="front_left_wheel_steering_link"/>
    <parent link="base_link"/>
    <axis xyz="0 0 1"/>
    <limit effort="25" lower="-0.6" upper="+0.6" velocity="1.0"/>
    <origin rpy="0 0 0" xyz="0.1575 0.1025 0.055"/>
  </joint>
  <joint name="front_right_wheel_steering_joint" type="revolute">
    <child link="front_right_wheel_steering_link"/>
    <parent link="base_link"/>
    <axis xyz="0 0 1"/>
    <limit effort="25" lower="-0.6" upper="+0.6" velocity="1.0"/>
    <origin rpy="0 0 0" xyz="0.1575 -0.1025 0.055"/>
  </joint>
  <!-- Drive joints -->
  <joint name="front_left_wheel_joint" type="continuous">
    <child link="front_left_wheel"/>
    <parent link="front_left_wheel_steering_link"/>
    <axis xyz="0 1 0"/>
  </joint>
  <joint name="front_right_wheel_joint" type="continuous">
    <child link="front_right_wheel"/>
    <parent link="front_right_wheel_steering_link"/>
    <axis xyz="0 1 0"/>
  </joint>
  <joint name="rear_left_wheel_joint" type="continuous">
    <child link="rear_left_wheel"/>
    <parent link="base_link"/>
    <axis xyz="0 1 0"/>
    <origin rpy="0 0 0" xyz="-0.1575 0.1025 0.055"/>
  </joint>
  <joint name="rear_right_wheel_joint" type="continuous">
    <child link="rear_right_wheel"/>
    <parent link="base_link"/>
    <axis xyz="0 1 0"/>
    <origin rpy="0 0 0" xyz="-0.1575 -0.1025 0.055"/>
  </joint>
  <!-- Chassis Joints-->
  <joint name="base_link_to_lower_chassis" type="fixed">
    <child link="lower_chassis"/>
    <parent link="base_link"/>
    <origin rpy="0 0 0" xyz="-0.155 0.09 0.055"/>
  </joint>
  <gazebo>
    <plugin filename="gz-sim-ackermann-steering-system" name="gz::sim::systems::AckermannSteering">
      <left_joint>front_left_wheel_joint</left_joint>
      <left_joint>rear_left_wheel_joint</left_joint>
      <right_joint>front_right_wheel_joint</right_joint>
      <right_joint>rear_right_wheel_joint</right_joint>
      <left_steering_joint>front_left_wheel_steering_joint</left_steering_joint>
      <right_steering_joint>front_right_wheel_steering_joint</right_steering_joint>
      <!-- TODO: change these numbers so that it is remotely accurate -->
      <kingpin_width>1.0</kingpin_width>
      <steering_limit>0.5</steering_limit>
      <wheel_base>1.0</wheel_base>
      <wheel_separation>1.25</wheel_separation>
      <wheel_radius>0.3</wheel_radius>
      <min_velocity>-1</min_velocity>
      <max_velocity>1</max_velocity>
      <min_acceleration>-3</min_acceleration>
      <max_acceleration>3</max_acceleration>
    </plugin>
  </gazebo>
</robot>
